Workbook

Sheet Indv. stocks
A1: Date | B1: Close | C1: R_MSFT | E1: Date | F1: Close | G1: R_NVDA | I1: Date | J1: Close | K1: R_PG | M1: Date | N1: Close | O1: R_KO | Q1: Date | R1: Close | S1: R_MNST | U1: Date | V1: Close | W1: R_SPX / R_M | Y1: Date | Z1: Value | AA1: R_P | AC1: Stock | AD1: Quatity | AF1: Date | AG1: R_F
A2: 45917 | B2: 510.02 | E2: 45917 | F2: 170.29 | I2: 45917 | J2: 160.33 | M2: 45917 | N2: 67.04 | Q2: 45917 | R2: 66.52 | U2: 45917 | V2: 6600.35 | Y2: 45917 | Z2: =(($AD$2*J2)+($AD$3*N2)+($AD$4*R2)+($AD$5*R60)+($AD$6*J60)+($AD$7*N60)+($AD$8*B2)+($AD$9*F2)+($AD$10*B60)+($AD$11*F60)) -> 98023.45 | AC2: PG | AD2: 68 | AF2: 45917 | AG2: 0.000154 | AX2: 0.02
A3: 45918 | B3: 508.45 | C3: =LN(B3/B2) -> -0.0030830584 | E3: 45918 | F3: 176.24 | G3: =LN(F3/F2) -> 0.034343836 | I3: 45918 | J3: 157.32 | K3: =LN(J3/J2) -> -0.018952244 | M3: 45918 | N3: 66.46 | O3: =LN(N3/N2) -> -0.0086891932 | Q3: 45918 | R3: 64.64 | S3: =LN(R3/R2) -> -0.02866924 | U3: 45918 | V3: 6631.96 | W3: =LN(V3/V2) -> 0.0047777085 | Y3: 45918 | Z3: =(($AD$2*J3)+($AD$3*N3)+($AD$4*R3)+($AD$5*R61)+($AD$6*J61)+($AD$7*N61)+($AD$8*B3)+($AD$9*F3)+($AD$10*B61)+($AD$11*F61)) -> 98239.49 | AA3: =LN(Z3/Z2) -> 0.0022015373 | AC3: KO | AD3: 164 | AF3: 45918 | AG3: 0.000154 | AX3: 0.02
A4: 45919 | B4: 517.93 | C4: =LN(B4/B3) -> 0.018473216 | E4: 45919 | F4: 176.67 | G4: =LN(F4/F3) -> 0.0024368831 | I4: 45919 | J4: 156.04 | K4: =LN(J4/J3) -> -0.0081695629 | M4: 45919 | N4: 66.43 | O4: =LN(N4/N3) -> -0.00045150125 | Q4: 45919 | R4: 64.13 | S4: =LN(R4/R3) -> -0.0079211411 | U4: 45919 | V4: 6664.36 | W4: =LN(V4/V3) -> 0.0048735386 | Y4: 45919 | Z4: =(($AD$2*J4)+($AD$3*N4)+($AD$4*R4)+($AD$5*R62)+($AD$6*J62)+($AD$7*N62)+($AD$8*B4)+($AD$9*F4)+($AD$10*B62)+($AD$11*F62)) -> 98073.07 | AA4: =LN(Z4/Z3) -> -0.0016954599 | AC4: MNST | AD4: 159 | AF4: 45919 | AG4: 0.000154 | AX4: 0.01
A5: 45922 | B5: 514.45 | C5: =LN(B5/B4) -> -0.0067417292 | E5: 45922 | F5: 183.61 | G5: =LN(F5/F4) -> 0.038530357 | I5: 45922 | J5: 153.07 | K5: =LN(J5/J4) -> -0.019217052 | M5: 45922 | N5: 66.21 | O5: =LN(N5/N4) -> -0.0033172527 | Q5: 45922 | R5: 63.98 | S5: =LN(R5/R4) -> -0.0023417386 | U5: 45922 | V5: 6693.75 | W5: =LN(V5/V4) -> 0.0044003302 | Y5: 45922 | Z5: =(($AD$2*J5)+($AD$3*N5)+($AD$4*R5)+($AD$5*R63)+($AD$6*J63)+($AD$7*N63)+($AD$8*B5)+($AD$9*F5)+($AD$10*B63)+($AD$11*F63)) -> 98242.2 | AA5: =LN(Z5/Z4) -> 0.0017230452 | AC5: HSY | AD5: 60 | AF5: 45922 | AG5: 0.000153 | AX5: 0.02
A6: 45923 | B6: 509.23 | C6: =LN(B6/B5) -> -0.010198588 | E6: 45923 | F6: 178.43 | G6: =LN(F6/F5) -> -0.028617575 | I6: 45923 | J6: 152.5 | K6: =LN(J6/J5) -> -0.0037307371 | M6: 45923 | N6: 66.71 | O6: =LN(N6/N5) -> 0.0075233578 | Q6: 45923 | R6: 64.48 | S6: =LN(R6/R5) -> 0.0077845637 | U6: 45923 | V6: 6656.92 | W6: =LN(V6/V5) -> -0.0055173401 | Y6: 45923 | Z6: =(($AD$2*J6)+($AD$3*N6)+($AD$4*R6)+($AD$5*R64)+($AD$6*J64)+($AD$7*N64)+($AD$8*B6)+($AD$9*F6)+($AD$10*B64)+($AD$11*F64)) -> 98012.39 | AA6: =LN(Z6/Z5) -> -0.002341959 | AC6: NVO | AD6: 197 | AF6: 45923 | AG6: 0.000153 | AX6: 0.02
A7: 45924 | B7: 510.15 | C7: =LN(B7/B6) -> 0.0018050192 | E7: 45924 | F7: 176.97 | G7: =LN(F7/F6) -> -0.0082161408 | I7: 45924 | J7: 152.42 | K7: =LN(J7/J6) -> -0.00052472781 | M7: 45924 | N7: 66.45 | O7: =LN(N7/N6) -> -0.0039050816 | Q7: 45924 | R7: 64.93 | S7: =LN(R7/R6) -> 0.0069546683 | U7: 45924 | V7: 6637.97 | W7: =LN(V7/V6) -> -0.0028507213 | Y7: 45924 | Z7: =(($AD$2*J7)+($AD$3*N7)+($AD$4*R7)+($AD$5*R65)+($AD$6*J65)+($AD$7*N65)+($AD$8*B7)+($AD$9*F7)+($AD$10*B65)+($AD$11*F65)) -> 97996.01 | AA7: =LN(Z7/Z6) -> -0.00016713569 | AC7: NVS | AD7: 93 | AF7: 45924 | AG7: 0.000153 | AX7: 0.02
A8: 45925 | B8: 507.03 | C8: =LN(B8/B7) -> -0.0061346267 | E8: 45925 | F8: 177.69 | G8: =LN(F8/F7) -> 0.0040602323 | I8: 45925 | J8: 152.15 | K8: =LN(J8/J7) -> -0.0017729919 | M8: 45925 | N8: 65.98 | O8: =LN(N8/N7) -> -0.0070981194 | Q8: 45925 | R8: 64.59 | S8: =LN(R8/R7) -> -0.0052501665 | U8: 45925 | V8: 6604.72 | W8: =LN(V8/V7) -> -0.0050216489 | Y8: 45925 | Z8: =(($AD$2*J8)+($AD$3*N8)+($AD$4*R8)+($AD$5*R66)+($AD$6*J66)+($AD$7*N66)+($AD$8*B8)+($AD$9*F8)+($AD$10*B66)+($AD$11*F66)) -> 96850.22 | AA8: =LN(Z8/Z7) -> -0.011761102 | AC8: MSFT | AD8: 11 | AF8: 45925 | AG8: 0.000154 | AX8: 0.02
A9: 45926 | B9: 511.46 | C9: =LN(B9/B8) -> 0.0086992075 | E9: 45926 | F9: 178.19 | G9: =LN(F9/F8) -> 0.0028099378 | I9: 45926 | J9: 152.5 | K9: =LN(J9/J8) -> 0.0022977197 | M9: 45926 | N9: 65.67 | O9: =LN(N9/N8) -> -0.0047094656 | Q9: 45926 | R9: 65.34 | S9: =LN(R9/R8) -> 0.011544806 | U9: 45926 | V9: 6643.7 | W9: =LN(V9/V8) -> 0.0058844923 | Y9: 45926 | Z9: =(($AD$2*J9)+($AD$3*N9)+($AD$4*R9)+($AD$5*R67)+($AD$6*J67)+($AD$7*N67)+($AD$8*B9)+($AD$9*F9)+($AD$10*B67)+($AD$11*F67)) -> 97408.27 | AA9: =LN(Z9/Z8) -> 0.0057454532 | AC9: NVDA | AD9: 35 | AF9: 45926 | AG9: 0.000153 | AX9: 0.02
A10: 45929 | B10: 514.6 | C10: =LN(B10/B9) -> 0.0061205189 | E10: 45929 | F10: 181.85 | G10: =LN(F10/F9) -> 0.020331775 | I10: 45929 | J10: 153.53 | K10: =LN(J10/J9) -> 0.0067313916 | M10: 45929 | N10: 66.04 | O10: =LN(N10/N9) -> 0.0056184188 | Q10: 45929 | R10: 66.96 | S10: =LN(R10/R9) -> 0.02449102 | U10: 45929 | V10: 6661.21 | W10: =LN(V10/V9) -> 0.0026321125 | Y10: 45929 | Z10: =(($AD$2*J10)+($AD$3*N10)+($AD$4*R10)+($AD$5*R68)+($AD$6*J68)+($AD$7*N68)+($AD$8*B10)+($AD$9*F10)+($AD$10*B68)+($AD$11*F68)) -> 97606.7 | AA10: =LN(Z10/Z9) -> 0.002035024 | AC10: LMT | AD10: 21 | AF10: 45929 | AG10: 0.000153 | AX10: 0.02
A11: 45930 | B11: 517.95 | C11: =LN(B11/B10) -> 0.0064888127 | E11: 45930 | F11: 186.58 | G11: =LN(F11/F10) -> 0.02567793 | I11: 45930 | J11: 153.56 | K11: =LN(J11/J10) -> 0.00019538246 | M11: 45930 | N11: 66.32 | O11: =LN(N11/N10) -> 0.0042308918 | Q11: 45930 | R11: 67.31 | S11: =LN(R11/R10) -> 0.0052133878 | U11: 45930 | V11: 6688.46 | W11: =LN(V11/V10) -> 0.0040825036 | Y11: 45930 | Z11: =(($AD$2*J11)+($AD$3*N11)+($AD$4*R11)+($AD$5*R69)+($AD$6*J69)+($AD$7*N69)+($AD$8*B11)+($AD$9*F11)+($AD$10*B69)+($AD$11*F69)) -> 98456.53 | AA11: =LN(Z11/Z10) -> 0.0086689924 | AC11: TTE | AD11: 163 | AF11: 45930 | AG11: 0.000153 | AX11: 0.03
A12: 45931 | B12: 519.71 | C12: =LN(B12/B11) -> 0.0033922512 | E12: 45931 | F12: 187.24 | G12: =LN(F12/F11) -> 0.0035311149 | I12: 45931 | J12: 153.18 | K12: =LN(J12/J11) -> -0.0024776697 | M12: 45931 | N12: 66.78 | O12: =LN(N12/N11) -> 0.0069121237 | Q12: 45931 | R12: 67.43 | S12: =LN(R12/R11) -> 0.0017812087 | U12: 45931 | V12: 6711.2 | W12: =LN(V12/V11) -> 0.0033941192 | Y12: 45931 | Z12: =(($AD$2*J12)+($AD$3*N12)+($AD$4*R12)+($AD$5*R70)+($AD$6*J70)+($AD$7*N70)+($AD$8*B12)+($AD$9*F12)+($AD$10*B70)+($AD$11*F70)) -> 99843.57 | AA12: =LN(Z12/Z11) -> 0.01398953 | AF12: 45931 | AG12: 0.000153 | AX12: 0.03
A13: 45932 | B13: 515.74 | C13: =LN(B13/B12) -> -0.0076682012 | E13: 45932 | F13: 188.89 | G13: =LN(F13/F12) -> 0.0087736186 | I13: 45932 | J13: 152.05 | K13: =LN(J13/J12) -> -0.0074042864 | M13: 45932 | N13: 66.1 | O13: =LN(N13/N12) -> -0.010234888 | Q13: 45932 | R13: 67.58 | S13: =LN(R13/R12) -> 0.0022220585 | U13: 45932 | V13: 6715.35 | W13: =LN(V13/V12) -> 0.00061817818 | Y13: 45932 | Z13: =(($AD$2*J13)+($AD$3*N13)+($AD$4*R13)+($AD$5*R71)+($AD$6*J71)+($AD$7*N71)+($AD$8*B13)+($AD$9*F13)+($AD$10*B71)+($AD$11*F71)) -> 99397.3 | AA13: =LN(Z13/Z12) -> -0.0044797109 | AF13: 45932 | AG13: 0.000153 | AX13: 0.03
A14: 45933 | B14: 517.35 | C14: =LN(B14/B13) -> 0.0031168655 | E14: 45933 | F14: 187.62 | G14: =LN(F14/F13) -> -0.0067461943 | I14: 45933 | J14: 152.27 | K14: =LN(J14/J13) -> 0.0014458467 | M14: 45933 | N14: 66.65 | O14: =LN(N14/N13) -> 0.0082862998 | Q14: 45933 | R14: 67.17 | S14: =LN(R14/R13) -> -0.006085362 | U14: 45933 | V14: 6715.79 | W14: =LN(V14/V13) -> 6.5519383e-05 | Y14: 45933 | Z14: =(($AD$2*J14)+($AD$3*N14)+($AD$4*R14)+($AD$5*R72)+($AD$6*J72)+($AD$7*N72)+($AD$8*B14)+($AD$9*F14)+($AD$10*B72)+($AD$11*F72)) -> 100227.34 | AA14: =LN(Z14/Z13) -> 0.0083160554 | AF14: 45933 | AG14: 0.000153 | AX14: 0.03
A15: 45936 | B15: 528.57 | C15: =LN(B15/B14) -> 0.021455619 | E15: 45936 | F15: 185.54 | G15: =LN(F15/F14) -> -0.011148148 | I15: 45936 | J15: 150.41 | K15: =LN(J15/J14) -> -0.012290362 | M15: 45936 | N15: 66.1 | O15: =LN(N15/N14) -> -0.0082862998 | Q15: 45936 | R15: 67.09 | S15: =LN(R15/R14) -> -0.0011917177 | U15: 45936 | V15: 6740.28 | W15: =LN(V15/V14) -> 0.003639997 | Y15: 45936 | Z15: =(($AD$2*J15)+($AD$3*N15)+($AD$4*R15)+($AD$5*R73)+($AD$6*J73)+($AD$7*N73)+($AD$8*B15)+($AD$9*F15)+($AD$10*B73)+($AD$11*F73)) -> 100258.64 | AA15: =LN(Z15/Z14) -> 0.00031224129 | AF15: 45936 | AG15: 0.000153 | AX15: 0.03
A16: 45937 | B16: 523.98 | C16: =LN(B16/B15) -> -0.0087217312 | E16: 45937 | F16: 185.04 | G16: =LN(F16/F15) -> -0.0026984743 | I16: 45937 | J16: 152.54 | K16: =LN(J16/J15) -> 0.014061958 | M16: 45937 | N16: 66.79 | O16: =LN(N16/N15) -> 0.010384622 | Q16: 45937 | R16: 68.15 | S16: =LN(R16/R15) -> 0.015676157 | U16: 45937 | V16: 6714.59 | W16: =LN(V16/V15) -> -0.0038186963 | Y16: 45937 | Z16: =(($AD$2*J16)+($AD$3*N16)+($AD$4*R16)+($AD$5*R74)+($AD$6*J74)+($AD$7*N74)+($AD$8*B16)+($AD$9*F16)+($AD$10*B74)+($AD$11*F74)) -> 100248.81 | AA16: =LN(Z16/Z15) -> -9.805122e-05 | AF16: 45937 | AG16: 0.000152 | AX16: 0.04
A17: 45938 | B17: 524.85 | C17: =LN(B17/B16) -> 0.0016589918 | E17: 45938 | F17: 189.11 | G17: =LN(F17/F16) -> 0.021756838 | I17: 45938 | J17: 150.69 | K17: =LN(J17/J16) -> -0.01220211 | M17: 45938 | N17: 66.12 | O17: =LN(N17/N16) -> -0.010082096 | Q17: 45938 | R17: 68.73 | S17: =LN(R17/R16) -> 0.008474627 | U17: 45938 | V17: 6753.72 | W17: =LN(V17/V16) -> 0.0058106934 | Y17: 45938 | Z17: =(($AD$2*J17)+($AD$3*N17)+($AD$4*R17)+($AD$5*R75)+($AD$6*J75)+($AD$7*N75)+($AD$8*B17)+($AD$9*F17)+($AD$10*B75)+($AD$11*F75)) -> 100528.56 | AA17: =LN(Z17/Z16) -> 0.0027866704 | AF17: 45938 | AG17: 0.000152
A18: 45939 | B18: 522.4 | C18: =LN(B18/B17) -> -0.0046789295 | E18: 45939 | F18: 192.57 | G18: =LN(F18/F17) -> 0.018130868 | I18: 45939 | J18: 150.58 | K18: =LN(J18/J17) -> -0.00073024201 | M18: 45939 | N18: 66.37 | O18: =LN(N18/N17) -> 0.0037738742 | Q18: 45939 | R18: 69.03 | S18: =LN(R18/R17) -> 0.0043554076 | U18: 45939 | V18: 6735.11 | W18: =LN(V18/V17) -> -0.0027593219 | Y18: 45939 | Z18: =(($AD$2*J18)+($AD$3*N18)+($AD$4*R18)+($AD$5*R76)+($AD$6*J76)+($AD$7*N76)+($AD$8*B18)+($AD$9*F18)+($AD$10*B76)+($AD$11*F76)) -> 100017.77 | AA18: =LN(Z18/Z17) -> -0.005093996 | AF18: 45939 | AG18: 0.000153
A19: 45940 | B19: 510.96 | C19: =LN(B19/B18) -> -0.022142269 | E19: 45940 | F19: 183.16 | G19: =LN(F19/F18) -> -0.050099636 | I19: 45940 | J19: 149.69 | K19: =LN(J19/J18) -> -0.0059280155 | M19: 45940 | N19: 67.04 | O19: =LN(N19/N18) -> 0.010044309 | Q19: 45940 | R19: 69.62 | S19: =LN(R19/R18) -> 0.0085106897 | U19: 45940 | V19: 6552.51 | W19: =LN(V19/V18) -> -0.02748596 | Y19: 45940 | Z19: =(($AD$2*J19)+($AD$3*N19)+($AD$4*R19)+($AD$5*R77)+($AD$6*J77)+($AD$7*N77)+($AD$8*B19)+($AD$9*F19)+($AD$10*B77)+($AD$11*F77)) -> 98982.44 | AA19: =LN(Z19/Z18) -> -0.01040541 | AF19: 45940 | AG19: 0.000153
A20: 45943 | B20: 514.05 | C20: =LN(B20/B19) -> 0.0060292277 | E20: 45943 | F20: 188.32 | G20: =LN(F20/F19) -> 0.027782556 | I20: 45943 | J20: 147.69 | K20: =LN(J20/J19) -> -0.013451006 | M20: 45943 | N20: 66.8 | O20: =LN(N20/N19) -> -0.0035863756 | Q20: 45943 | R20: 67.15 | S20: =LN(R20/R19) -> -0.036122959 | U20: 45943 | V20: 6654.72 | W20: =LN(V20/V19) -> 0.015478195 | Y20: 45943 | Z20: =(($AD$2*J20)+($AD$3*N20)+($AD$4*R20)+($AD$5*R78)+($AD$6*J78)+($AD$7*N78)+($AD$8*B20)+($AD$9*F20)+($AD$10*B78)+($AD$11*F78)) -> 98488.98 | AA20: =LN(Z20/Z19) -> -0.0049977969 | AF20: 45943 | AG20: 0.000153
A21: 45944 | B21: 513.57 | C21: =LN(B21/B20) -> -0.00093419753 | E21: 45944 | F21: 180.03 | G21: =LN(F21/F20) -> -0.04501914 | I21: 45944 | J21: 149.16 | K21: =LN(J21/J20) -> 0.0099040729 | M21: 45944 | N21: 67.51 | O21: =LN(N21/N20) -> 0.010572655 | Q21: 45944 | R21: 68.61 | S21: =LN(R21/R20) -> 0.021509374 | U21: 45944 | V21: 6644.31 | W21: =LN(V21/V20) -> -0.001565528 | Y21: 45944 | Z21: =(($AD$2*J21)+($AD$3*N21)+($AD$4*R21)+($AD$5*R79)+($AD$6*J79)+($AD$7*N79)+($AD$8*B21)+($AD$9*F21)+($AD$10*B79)+($AD$11*F79)) -> 98750.29 | AA21: =LN(Z21/Z20) -> 0.0026496767 | AF21: 45944 | AG21: 0.000153
A22: 45945 | B22: 513.43 | C22: =LN(B22/B21) -> -0.00027263876 | E22: 45945 | F22: 179.83 | G22: =LN(F22/F21) -> -0.0011115435 | I22: 45945 | J22: 147.42 | K22: =LN(J22/J21) -> -0.0117339 | M22: 45945 | N22: 67.08 | O22: =LN(N22/N21) -> -0.0063897981 | Q22: 45945 | R22: 68.65 | S22: =LN(R22/R21) -> 0.00058283551 | U22: 45945 | V22: 6671.06 | W22: =LN(V22/V21) -> 0.0040179185 | Y22: 45945 | Z22: =(($AD$2*J22)+($AD$3*N22)+($AD$4*R22)+($AD$5*R80)+($AD$6*J80)+($AD$7*N80)+($AD$8*B22)+($AD$9*F22)+($AD$10*B80)+($AD$11*F80)) -> 98896.48 | AA22: =LN(Z22/Z21) -> 0.001479306 | AF22: 45945 | AG22: 0.000153
A23: 45946 | B23: 511.61 | C23: =LN(B23/B22) -> -0.0035510847 | E23: 45946 | F23: 181.81 | G23: =LN(F23/F22) -> 0.010950226 | I23: 45946 | J23: 149.6 | K23: =LN(J23/J22) -> 0.01467941 | M23: 45946 | N23: 67.59 | O23: =LN(N23/N22) -> 0.0075741062 | Q23: 45946 | R23: 70.16 | S23: =LN(R23/R22) -> 0.021757216 | U23: 45946 | V23: 6629.07 | W23: =LN(V23/V22) -> -0.006314245 | Y23: 45946 | Z23: =(($AD$2*J23)+($AD$3*N23)+($AD$4*R23)+($AD$5*R81)+($AD$6*J81)+($AD$7*N81)+($AD$8*B23)+($AD$9*F23)+($AD$10*B81)+($AD$11*F81)) -> 98947.57 | AA23: =LN(Z23/Z22) -> 0.0005164674 | AF23: 45946 | AG23: 0.000153
A24: 45947 | B24: 513.58 | C24: =LN(B24/B23) -> 0.0038431948 | E24: 45947 | F24: 183.22 | G24: =LN(F24/F23) -> 0.0077254309 | I24: 45947 | J24: 151.4 | K24: =LN(J24/J23) -> 0.011960275 | M24: 45947 | N24: 68.44 | O24: =LN(N24/N23) -> 0.012497406 | Q24: 45947 | R24: 70.22 | S24: =LN(R24/R23) -> 0.00085482268 | U24: 45947 | V24: 6664.01 | W24: =LN(V24/V23) -> 0.0052568826 | Y24: 45947 | Z24: =(($AD$2*J24)+($AD$3*N24)+($AD$4*R24)+($AD$5*R82)+($AD$6*J82)+($AD$7*N82)+($AD$8*B24)+($AD$9*F24)+($AD$10*B82)+($AD$11*F82)) -> 99295.62 | AA24: =LN(Z24/Z23) -> 0.0035113474 | AF24: 45947 | AG24: 0.000152
A25: 45950 | B25: 516.79 | C25: =LN(B25/B24) -> 0.0062307916 | E25: 45950 | F25: 182.64 | G25: =LN(F25/F24) -> -0.0031706144 | I25: 45950 | J25: 151.96 | K25: =LN(J25/J24) -> 0.0036919873 | M25: 45950 | N25: 68.44 | O25: =LN(N25/N24) -> 0 | Q25: 45950 | R25: 69.76 | S25: =LN(R25/R24) -> -0.0065723911 | U25: 45950 | V25: 6735.13 | W25: =LN(V25/V24) -> 0.010615706 | Y25: 45950 | Z25: =(($AD$2*J25)+($AD$3*N25)+($AD$4*R25)+($AD$5*R83)+($AD$6*J83)+($AD$7*N83)+($AD$8*B25)+($AD$9*F25)+($AD$10*B83)+($AD$11*F83)) -> 99624.44 | AA25: =LN(Z25/Z24) -> 0.0033060547 | AF25: 45950 | AG25: 0.000151
A26: 45951 | B26: 517.66 | C26: =LN(B26/B25) -> 0.0016820537 | E26: 45951 | F26: 181.16 | G26: =LN(F26/F25) -> -0.0081363835 | I26: 45951 | J26: 151.62 | K26: =LN(J26/J25) -> -0.0022399377 | M26: 45951 | N26: 71.22 | O26: =LN(N26/N25) -> 0.039816229 | Q26: 45951 | R26: 68.9 | S26: =LN(R26/R25) -> -0.012404602 | U26: 45951 | V26: 6735.35 | W26: =LN(V26/V25) -> 3.2664018e-05 | Y26: 45951 | Z26: =(($AD$2*J26)+($AD$3*N26)+($AD$4*R26)+($AD$5*R84)+($AD$6*J84)+($AD$7*N84)+($AD$8*B26)+($AD$9*F26)+($AD$10*B84)+($AD$11*F84)) -> 99289.95 | AA26: =LN(Z26/Z25) -> -0.0033631585 | AF26: 45951 | AG26: 0.00015
A27: 45952 | B27: 520.54 | C27: =LN(B27/B26) -> 0.0055480782 | E27: 45952 | F27: 180.28 | G27: =LN(F27/F26) -> -0.0048694209 | I27: 45952 | J27: 152.2 | K27: =LN(J27/J26) -> 0.0038180548 | M27: 45952 | N27: 70.81 | O27: =LN(N27/N26) -> -0.0057734442 | Q27: 45952 | R27: 69.72 | S27: =LN(R27/R26) -> 0.011831043 | U27: 45952 | V27: 6699.4 | W27: =LN(V27/V26) -> -0.0053518057 | Y27: 45952 | Z27: =(($AD$2*J27)+($AD$3*N27)+($AD$4*R27)+($AD$5*R85)+($AD$6*J85)+($AD$7*N85)+($AD$8*B27)+($AD$9*F27)+($AD$10*B85)+($AD$11*F85)) -> 99166.6 | AA27: =LN(Z27/Z26) -> -0.0012430934 | AF27: 45952 | AG27: 0.00015
A28: 45953 | B28: 520.56 | C28: =LN(B28/B27) -> 3.8420901e-05 | E28: 45953 | F28: 182.16 | G28: =LN(F28/F27) -> 0.010374224 | I28: 45953 | J28: 152.21 | K28: =LN(J28/J27) -> 6.5700864e-05 | M28: 45953 | N28: 69.94 | O28: =LN(N28/N27) -> -0.012362502 | Q28: 45953 | R28: 69.89 | S28: =LN(R28/R27) -> 0.0024353568 | U28: 45953 | V28: 6738.44 | W28: =LN(V28/V27) -> 0.005810474 | Y28: 45953 | Z28: =(($AD$2*J28)+($AD$3*N28)+($AD$4*R28)+($AD$5*R86)+($AD$6*J86)+($AD$7*N86)+($AD$8*B28)+($AD$9*F28)+($AD$10*B86)+($AD$11*F86)) -> 99024.53 | AA28: =LN(Z28/Z27) -> -0.0014336668 | AF28: 45953 | AG28: 0.00015
... A48: 45981 | B48: 478.43 | C48: =LN(B48/B47) -> -0.01800059 | E48: 45981 | F48: 180.64 | G48: =LN(F48/F47) -> -0.032032372 | I48: 45981 | J48: 148.19 | K48: =LN(J48/J47) -> 0.0081306769 | M48: 45981 | N48: 71.21 | O48: =LN(N48/N47) -> 0.0014052841 | Q48: 45981 | R48: 72.22 | S48: =LN(R48/R47) -> -0.0011071133 | U48: 45981 | V48: 6538.76 | W48: =LN(V48/V47) -> -0.015689667 | Y48: 45981 | Z48: =(($AD$2*J48)+($AD$3*N48)+($AD$4*R48)+($AD$5*R106)+($AD$6*J106)+($AD$7*N106)+($AD$8*B48)+($AD$9*F48)+($AD$10*B106)+($AD$11*F106)) -> 96904.82 | AA48: =LN(Z48/Z47) -> -0.0093209741 | AF48: 45981 | AG48: 0.00015
A49: MSFT | B49: Total | C49: =AVERAGEA(C3:C48) -> -0.0013900007 | E49: NVDA | F49: Total | G49: =AVERAGEA(G3:G48) -> 0.001282679 | I49: PG | J49: Total | K49: =AVERAGEA(K3:K48) -> -0.0017117165 | M49: KO | N49: Total | O49: =AVERAGEA(O3:O48) -> 0.0013118218 | Q49: MNST | R49: Total | S49: =AVERAGEA(S3:S48) -> 0.0017872687 | U49: Market | V49: Total | W49: =AVERAGE(W3:W48) -> -0.00020380724 | Z49: Total | AA49: =AVERAGE(AA3:AA48) -> -0.00024951035 | AF49: Total | AG49: =AVERAGE(AG2:AG48) -> 0.00015125532
B50: StDev | C50: =_xlfn.STDEV.S(C3:C48) -> 0.011883725 | F50: StDev | G50: =_xlfn.STDEV.S(G3:G48) -> 0.025274548 | J50: StDev | K50: =_xlfn.STDEV.S(K3:K48) -> 0.00915194 | N50: StDev | O50: =_xlfn.STDEV.S(O3:O48) -> 0.010508532 | R50: StDev | S50: =_xlfn.STDEV.S(S3:S48) -> 0.015824553 | V50: StDev | W50: =_xlfn.STDEV.S(W3:W48) -> 0.0082465423 | Z50: StDev | AA50: =_xlfn.STDEV.S(AA3:AA48) -> 0.0064256582 | AF50: StDev | AG50: =_xlfn.STDEV.S(AG2:AG48) -> 1.9050058e-06
B51: Covariance | C51: =_xlfn.COVARIANCE.S(C3:C48,W3:W48) -> 6.5436591e-05 | F51: Covariance | G51: =_xlfn.COVARIANCE.S(G3:G48,W3:W48) -> 0.00015022099 | J51: Covariance | K51: =_xlfn.COVARIANCE.S(K3:K48,W3:W48) -> -1.6782594e-05 | N51: Covariance | O51: =_xlfn.COVARIANCE.S(O3:O48,W3:W48) -> -1.6070941e-05 | R51: Covariance | S51: =_xlfn.COVARIANCE.S(S3:S48,W3:W48) -> -2.4568345e-05 | V51: Covariance | W51: =_xlfn.COVARIANCE.S(W3:W48,W3:W48) -> 6.8005461e-05 | Z51: Covariance | AA51: =_xlfn.COVARIANCE.S(W3:W48,AA3:AA48) -> 2.3177352e-05
B52: Variance | C52: =_xlfn.VAR.S(C3:C48) -> 0.00014122292 | F52: Variance | G52: =_xlfn.VAR.S(G3:G48) -> 0.00063880276 | J52: Variance | K52: =_xlfn.VAR.S(K3:K48) -> 8.3758006e-05 | N52: Variance | O52: =_xlfn.VAR.S(O3:O48) -> 0.00011042925 | R52: Variance | S52: =_xlfn.VAR.S(S3:S48) -> 0.00025041647 | V52: Variance | W52: =_xlfn.VAR.S(W3:W48) -> 6.8005461e-05 | Z52: Variance | AA52: =_xlfn.VAR.S(AA3:AA48) -> 4.1289083e-05
B53: Beta | C53: =C51/W52 -> 0.96222554 | F53: Beta | G53: =G51/W52 -> 2.2089549 | J53: Beta | K53: 0.54 | N53: Beta | O53: 0.43 | R53: Beta | S53: 0.54 | V53: Beta | W53: =W51/W52 -> 1 | Z53: Beta | AA53: =AA51/AA52 -> 0.56134334
B54: Jensen Alpha | C54: =C49-(AG49+C53*(W49-AG49)) -> -0.0011996057 | F54: Jensen Alpha | G54: =G49-(0.02%+G53*(-0.06%-0.02%)) -> 0.0028498429 | J54: Jensen Alpha | K54: =K49-(0.02%+K53*(-0.06%-0.02%)) -> -0.0014797165 | N54: Jensen Alpha | O54: =O49-(0.02%+O53*(-0.06%-0.02%)) -> 0.0014558218 | R54: Jensen Alpha | S54: =S49-(0.02%+S53*(-0.06%-0.02%)) -> 0.0020192687 | V54: Jensen Alpha | W54: =W49-(0.02%+W53*(-0.06%-0.02%)) -> 0.00039619276 | Z54: Jensen Alpha | AA54: =AA49-(0.02%+AA53*(-0.06%-0.02%)) -> -4.3567947e-07
B55: Treynor I | C55: =(C49-0.02%)/C53 -> -0.0016524199 | F55: Treynor I | G55: =(G49-0.02%)/G53 -> 0.00049013179 | J55: Treynor I | K55: =(K49-0.02%)/K53 -> -0.0035402157 | N55: Treynor I | O55: =(O49-0.02%)/O53 -> 0.002585632 | R55: Treynor I | S55: =(S49-0.02%)/S53 -> 0.0029393865 | V55: Treynor I | W55: =(W49-0.02%)/W53 -> -0.00040380724 | Z55: Treynor I | AA55: =(AA49-0.02%)/AA53 -> -0.00080077614
B56: Sharpe | C56: =(C49-0.02%)/C50 -> -0.13379649 | F56: Sharpe | G56: =(G49-0.02%)/G50 -> 0.042836731 | J56: Sharpe | K56: =(K49-0.02%)/K50 -> -0.20888647 | N56: Sharpe | O56: =(O49-0.02%)/O50 -> 0.10580182 | R56: Sharpe | S56: =(S49-0.02%)/S50 -> 0.10030418 | V56: Sharpe | W56: =(W49-0.02%)/W50 -> -0.048966854 | Z56: Sharpe | AA56: =(AA49-0.02%)/AA50 -> -0.069955534
A59: Date | B59: Close | C59: R_LMT | E59: Date | F59: Close | G59: R_TTE | I59: Date | J59: Close | K59: R_NVO | M59: Date | N59: Close | O59: R_NVS | Q59: Date | R59: Close | S59: R_HSY
A60: 45917 | B60: 473.12 | E60: 45917 | F60: 60.19 | I60: 45917 | J60: 58.2 | M60: 45917 | N60: 122.47 | Q60: 45917 | R60: 189.63
A61: 45918 | B61: 473.62 | C61: =LN(B61/B60) -> 0.0010562563 | E61: 45918 | F61: 60.38 | G61: =LN(F61/F60) -> 0.0031516987 | I61: 45918 | J61: 61.85 | K61: =LN(J61/J60) -> 0.060826744 | M61: 45918 | N61: 122.29 | O61: =LN(N61/N60) -> -0.0014708288 | Q61: 45918 | R61: 187.63 | S61: =LN(R61/R60) -> -0.010602867
...

Sheet HPR and risk
B1: Risk | E1: Performance
B2: Variance | C2: Standard. D | D2: Beta | E2: Mean | F2: Jensen Alpha | G2: Sharpe Ratio | H2: Treynor I | I2: Weight
A3: MSFT | B3: 0.00014122292 | C3: =SQRT(B3) -> 0.011883725 | D3: 0.96222554 | E3: ='Indv. stocks'!C49 -> -0.0013900007 | F3: ='Indv. stocks'!C54 -> -0.0011996057 | G3: ='Indv. stocks'!C56 -> -0.13379649 | H3: ='Indv. stocks'!C55 -> -0.0016524199 | I3: 0.06
A4: PG | B4: 8.3758006e-05 | C4: =SQRT(B4) -> 0.00915194 | D4: 0.54 | E4: ='Indv. stocks'!K49 -> -0.0017117165 | F4: ='Indv. stocks'!K54 -> -0.0014797165 | G4: ='Indv. stocks'!K56 -> -0.20888647 | H4: ='Indv. stocks'!K55 -> -0.0035402157 | I4: 0.11
A5: KO | B5: 0.00011042925 | C5: =SQRT(B5) -> 0.010508532 | D5: 0.43 | E5: ='Indv. stocks'!O49 -> 0.0013118218 | F5: ='Indv. stocks'!O54 -> 0.0014558218 | G5: ='Indv. stocks'!O56 -> 0.10580182 | H5: ='Indv. stocks'!O55 -> 0.002585632 | I5: 0.11
A6: MNST | B6: 0.00025041647 | C6: =SQRT(B6) -> 0.015824553 | D6: 0.54 | E6: ='Indv. stocks'!S49 -> 0.0017872687 | F6: ='Indv. stocks'!S54 -> 0.0020192687 | G6: ='Indv. stocks'!S56 -> 0.10030418 | H6: ='Indv. stocks'!S55 -> 0.0029393865 | I6: 0.115
A7: HSY | B7: 4.5113338e-06 | C7: =SQRT(B7) -> 0.0021239901 | D7: 0.26633782 | E7: ='Indv. stocks'!S107 -> -0.00081409356 | F7: ='Indv. stocks'!S112 -> 0.0025 | G7: ='Indv. stocks'!S114 -> 0.2201 | H7: ='Indv. stocks'!S113 -> 0.002 | I7: 0.115
A8: NVO | B8: 0.00058548429 | C8: =SQRT(B8) -> 0.024196783 | D8: 0.32 | E8: ='Indv. stocks'!K107 -> -0.0043707086 | F8: ='Indv. stocks'!K112 -> -0.0043147086 | G8: ='Indv. stocks'!K114 -> -0.18889737 | H8: ='Indv. stocks'!K113 -> -0.014283464 | I8: 0.115
A9: NVS | B9: 0.00016852584 | C9: =SQRT(B9) -> 0.01298175 | D9: 0.45 | E9: ='Indv. stocks'!O107 -> 0.00033292355 | F9: ='Indv. stocks'!O112 -> 0.00049292355 | G9: ='Indv. stocks'!O114 -> 0.010239262 | H9: ='Indv. stocks'!O113 -> 0.00029538566 | I9: 0.115
A10: NVDA | B10: 0.00063880276 | C10: =SQRT(B10) -> 0.025274548 | D10: 2.2089549 | E10: ='Indv. stocks'!G49 -> 0.001282679 | F10: ='Indv. stocks'!G54 -> 0.0028498429 | G10: ='Indv. stocks'!G56 -> 0.042836731 | H10: ='Indv. stocks'!G55 -> 0.00049013179 | I10: 0.06
A11: LMT | B11: 0.00013146495 | C11: =SQRT(B11) -> 0.011465816 | D11: 0.11923796 | E11: ='Indv. stocks'!C107 -> -0.00022446432 | F11: ='Indv. stocks'!C112 -> -0.00032907396 | G11: ='Indv. stocks'!C114 -> -0.037019983 | H11: ='Indv. stocks'!C113 -> -0.0035598087 | I11: 0.1
A12: TTE | B12: 0.00014685512 | C12: =SQRT(B12) -> 0.012118379 | D12: 0.71 | E12: ='Indv. stocks'!G107 -> 0.0011535028 | F12: ='Indv. stocks'!G112 -> 0.0015215028 | G12: ='Indv. stocks'!G114 -> 0.078682368 | H12: ='Indv. stocks'!G113 -> 0.0013429617 | I12: 0.1
A13: S&P 500 | B13: 6.8005461e-05 | C13: =SQRT(B13) -> 0.0082465423 | D13: 1 | E13: ='Indv. stocks'!W49 -> -0.00020380724 | F13: ='Indv. stocks'!W54 -> 0.00039619276 | G13: ='Indv. stocks'!W56 -> -0.048966854 | H13: ='Indv. stocks'!W55 -> -0.00040380724 | I13: 0
A14: Portfolio | B14: 4.1289083e-05 | C14: =SQRT(B14) -> 0.0064256582 | D14: 0.56134334 | E14: ='Indv. stocks'!AA49 -> -0.00024951035 | F14: ='Indv. stocks'!AA54 -> -4.3567947e-07 | G14: ='Indv. stocks'!AA56 -> -0.069955534 | H14: ='Indv. stocks'!AA55 -> -0.00080077614 | I14: =SUM(I3:I13) -> 1
K18: c

Sheet Prices 
A1: Symbol | B1: Description | C1: Quantity | D1: Last Price | E1: PricePaid | F1: Total Price | H1: Day Change | I1: Profit/Loss | J1: Market Value | K1: Profit/Loss Percentage | L1: Beginning proportion | M1: Closing proportion
A2: PG | B2: Procter & Gamble Company | C2: 68 | D2: 148.19 | E2: 160.33 | F2: =E2*C2 -> 10902.44 | H2: 0.0082 | I2: =(D2*C2)-F2 -> -825.52 | J2: =D2*C2 -> 10076.92 | K2: =(J2-F2)/F2*100 -> -7.571883 | L2: =C2*E2/$B$13 -> 0.11093915 | M2: =J2/$B$12 -> 0.10398781
A3: KO | B3: The Coca-Cola Company | C3: 164 | D3: 71.21 | E3: 67.04 | F3: =E3*C3 -> 10994.56 | H3: 0.14 | I3: =(D3*C3)-F3 -> 683.88 | J3: =D3*C3 -> 11678.44 | K3: =(J3-F3)/F3*100 -> 6.2201671 | L3: =C3*E3/$B$13 -> 0.11187653 | M3: =J3/$B$12 -> 0.12051454
A4: MNST | B4: Monster Beverage Corporation | C4: 159 | D4: 72.22 | E4: 66.52 | F4: =E4*C4 -> 10576.68 | H4: -0.11 | I4: =(D4*C4)-F4 -> 906.3 | J4: =D4*C4 -> 11482.98 | K4: =(J4-F4)/F4*100 -> 8.5688515 | L4: =C4*E4/$B$13 -> 0.10762434 | M4: =J4/$B$12 -> 0.11849751
A5: HSY | B5: The Hershey Company | C5: 60 | D5: 182.66 | E5: 191.09 | F5: =E5*C5 -> 11465.4 | H5: 0.001 | I5: =(D5*C5)-F5 -> -505.8 | J5: =D5*C5 -> 10959.6 | K5: =(J5-F5)/F5*100 -> -4.4115338 | L5: =C5*E5/$B$13 -> 0.11666762 | M5: =J5/$B$12 -> 0.11309654
A6: NVO | B6: Novo Nordisk A/S | C6: 197 | D6: 47.6 | E6: 58.2 | F6: =E6*C6 -> 11465.4 | H6: -0.0286 | I6: =(D6*C6)-F6 -> -2088.2 | J6: =D6*C6 -> 9377.2 | K6: =(J6-F6)/F6*100 -> -18.213058 | L6: =C6*E6/$B$13 -> 0.11666762 | M6: =J6/$B$12 -> 0.096767116
A7: NVS | B7: Novartis AG | C7: 93 | D7: 124.36 | E7: 122.47 | F7: =E7*C7 -> 11389.71 | H7: -0.0232 | I7: =(D7*C7)-F7 -> 175.77 | J7: =D7*C7 -> 11565.48 | K7: =(J7-F7)/F7*100 -> 1.5432351 | L7: =C7*E7/$B$13 -> 0.11589743 | M7: =J7/$B$12 -> 0.11934886
A8: MSFT | B8: Microsoft Corporation | C8: 11 | D8: 478.43 | E8: 510.02 | F8: =E8*C8 -> 5610.22 | H8: -0.0178 | I8: 12704.1 | J8: =D8*C8 -> 5262.73 | K8: =(J8-F8)/F8*100 -> -6.1938748 | L8: =C8*E8/$B$13 -> 0.057087502 | M8: =J8/$B$12 -> 0.054308238
A9: NVDA | B9: NVIDIA Corporation | C9: 35 | D9: 180.64 | E9: 170.29 | F9: =E9*C9 -> 5960.15 | H9: -0.0315 | I9: -743.4 | J9: =D9*C9 -> 6322.4 | K9: =(J9-F9)/F9*100 -> 6.0778672 | L9: =C9*E9/$B$13 -> 0.060648259 | M9: =J9/$B$12 -> 0.065243401
A10: LMT | B10: Lockheed Martin Corporation | C10: 21 | D10: 468.26 | E10: 473.12 | F10: =E10*C10 -> 9935.52 | H10: -0.0035 | I10: 19733.74 | J10: =D10*C10 -> 9833.46 | K10: =(J10-F10)/F10*100 -> -1.0272235 | L10: =C10*E10/$B$13 -> 0.10110014 | M10: =J10/$B$12 -> 0.10147545
A11: TTE | B11: TotalEnergies SE | C11: 163 | D11: 63.47 | E11: 61.19 | F11: =E11*C11 -> 9973.97 | H11: -0.0112 | I11: -9903.33 | J11: =D11*C11 -> 10345.61 | K11: =(J11-F11)/F11*100 -> 3.726099 | L11: =C11*E11/$B$13 -> 0.10149139 | M11: =J11/$B$12 -> 0.10676053
A12: Portfolio value | B12: =SUM(J2:J12) -> 96904.82
A13: Beginning value | B13: =SUM(F2:F11) -> 98274.05

Sheet 4 years Indv. stocks 
A1: Date | B1: Adj Close | C1: R_PG | D1: R_KO | E1: R_MNST | F1: R_HSY | G1: Adj Close | H1: R_MSFT | I1: Adj Close | J1: R_NVDA | K1: Adj Close | L1: R_LMT | M1: Adj Close | N1: R_TTE | O1: R_NVO | P1: R_NVS | Q1: R_SPY | R1: Close | T1: Close | V1: Date | W1: Close | Y1: Close | AA1: Data | AC1: Date
A3: Sep 17, 2025 | B3: 67.243767 | C3: =(AE4-AE4) -> 0 | D3: 0 | E3: 0 | F3: 0 | G3: 18.5 | H3: 0 | I3: 965.59003 | J3: 0 | K3: 27.874664 | L3: 0 | M3: 122.67579 | N3: 0 | O3: 0 | P3: 0 | Q3: -0.001 | R3: 125.05 | T3: 34.200001 | Y3: 243.13001
A4: Sep 18, 2025 | B4: 65.090744 | C4: =(AE5-AE4)/AE4 -> 0.0019638383 | D4: =(AF5-AF4)/AF4 -> -0.0086515513 | E4: =(AG5-AG4)/AG4 -> -0.028262177 | F4: =(AH5-AH4)/AH4 -> -0.010546854 | G4: 17.870001 | H4: =(AI5-AI4)/AI4 -> -0.0030783107 | I4: 908.72998 | J4: =(AI5-AI4)/AI4 -> -0.0030783107 | K4: 27.40152 | L4: =(AJ5-AJ4)/AJ4 -> 0.0010568143 | M4: 118.95319 | N4: =(AK5-AK4)/AK4 -> 0.0031566705 | O4: =(AL5-AL4)/AL4 -> 0.070266528 | P4: =(AM5-AM4)/AM4 -> -0.0014697477 | Q4: 0.0048 | AC4: 42909 | AE4: 147.67 | AF4: 67.04 | AG4: 66.52 | AH4: 189.63 | AI4: 510.02 | AJ4: 473.12 | AK4: 60.19 | AL4: 57.78 | AM4: 122.47
A5: Sep 19, 2025 | B5: 65.591217 | C5: =(AE6-AE5)/AE5 -> 0.00033792917 | D5: =(AF6-AF5)/AF5 -> -0.00045139934 | E5: =(AG6-AG5)/AG5 -> -0.0078898515 | F5: =(AH6-AH5)/AH5 -> 0.0058626019 | G5: 18.02 | H5: =(AI6-AI5)/AI5 -> 0.018644901 | I5: 918.59003 | J5: =(AI6-AI5)/AI5 -> 0.018644901 | K5: 27.205738 | L5: =(AJ6-AJ5)/AJ5 -> -0.0014357502 | M5: 119.17799 | N5: =(AK6-AK5)/AK5 -> -0.013746274 | O5: =(AL6-AL5)/AL5 -> 0.0074385511 | P5: =(AM6-AM5)/AM5 -> 0.0052334614 | Q5: 0.0049 | AC5: 42916 | AE5: 147.96 | AF5: 66.46 | AG5: 64.64 | AH5: 187.63 | AI5: 508.45 | AJ5: 473.62 | AK5: 60.38 | AL5: 61.84 | AM5: 122.29
A6: Sep 22, 2025 | B6: 68.726311 | C6: =(AE7-AE6)/AE6 -> 0.0035808391 | D6: =(AF7-AF6)/AF6 -> -0.0033117567 | E6: =(AG7-AG6)/AG6 -> -0.0023389989 | F6: =(AH7-AH6)/AH6 -> 0.01133895 | G6: 19.639999 | H6: =(AI7-AI6)/AI6 -> -0.0067190547 | I6: 955.98999 | J6: =(AI7-AI6)/AI6 -> -0.0067190547 | K6: 27.271 | L6: =(AJ7-AJ6)/AJ6 -> 0.015752527 | M6: 119.23194 | N6: =(AK7-AK6)/AK6 -> 0.0038623006 | O6: =(AL7-AL6)/AL6 -> -0.036918138 | P6: =(AM7-AM6)/AM6 -> 0.0034979256 | Q6: 0.0044 | AC6: 42923 | AE6: 148.01 | AF6: 66.43 | AG6: 64.13 | AH6: 188.73 | AI6: 517.93 | AJ6: 472.94 | AK6: 59.55 | AL6: 62.3 | AM6: 122.93
A7: Sep 23, 2025 | B7: 69.680061 | C7: =(AE8-AE7)/AE7 -> -0.020465868 | D7: =(AF8-AF7)/AF7 -> 0.0075517293 | E7: =(AG8-AG7)/AG7 -> 0.0078149422 | F7: =(AH8-AH7)/AH7 -> -0.0083302772 | G7: 20.110001 | H7: =(AI8-AI7)/AI7 -> -0.010146759 | I7: 972.91998 | J7: =(AI8-AI7)/AI7 -> -0.010146759 | K7: 27.311787 | L7: =(AJ8-AJ7)/AJ7 -> 0.013072712 | M7: 121.66872 | N7: =(AK8-AK7)/AK7 -> 0.013382402 | O7: =(AL8-AL7)/AL7 -> 0.005 | P7: =(AM8-AM7)/AM7 -> -0.0043774319 | Q7: -0.0055 | AC7: 42930 | AE7: 148.54 | AF7: 66.21 | AG7: 63.98 | AH7: 190.87 | AI7: 514.45 | AJ7: 480.39 | AK7: 59.78 | AL7: 60 | AM7: 123.36
A8: Sep 24, 2025 | B8: 68.971832 | C8: =(AE9-AE8)/AE8 -> 0.010171821 | D8: =(AF9-AF8)/AF8 -> -0.0038974666 | E8: =(AG9-AG8)/AG8 -> 0.0069789082 | F8: =(AH9-AH8)/AH8 -> 0.00079247675 | G8: 16.75 | H8: =(AI9-AI8)/AI8 -> 0.0018066493 | I8: 941.53003 | J8: =(AI9-AI8)/AI8 -> 0.0018066493 | K8: 27.042583 | L8: =(AJ9-AJ8)/AJ8 -> -0.00086300779 | M8: 118.55755 | N8: =(AK9-AK8)/AK8 -> 0.014361175 | O8: =(AL9-AL8)/AL8 -> -0.024046434 | P8: =(AM9-AM8)/AM8 -> 0.0014655594 | Q8: -0.0028 | AC8: 42937 | AE8: 145.5 | AF8: 66.71 | AG8: 64.48 | AH8: 189.28 | AI8: 509.23 | AJ8: 486.67 | AK8: 60.58 | AL8: 60.3 | AM8: 122.82
A9: Sep 25, 2025 | B9: 68.631882 | C9: =(AE10-AE9)/AE9 -> -0.0057830997 | D9: =(AF10-AF9)/AF9 -> -0.0070729872 | E9: =(AG10-AG9)/AG9 -> -0.0052364084 | F9: =(AH10-AH9)/AH9 -> -0.029509581 | G9: 16.290001 | H9: =(AI10-AI9)/AI9 -> -0.0061158483 | I9: 927.96002 | J9: =(AI10-AI9)/AI9 -> -0.0061158483 | K9: 27.442308 | L9: =(AJ10-AJ9)/AJ9 -> -0.0039280206 | M9: 119.75346 | N9: =(AK10-AK9)/AK9 -> -0.00081366965 | O9: =(AL10-AL9)/AL9 -> -0.029056924 | P9: =(AM10-AM9)/AM9 -> -0.0062601626 | Q9: -0.005 | AC9: 42944 | AE9: 146.98 | AF9: 66.45 | AG9: 64.93 | AH9: 189.43 | AI9: 510.15 | AJ9: 486.25 | AK9: 61.45 | AL9: 58.85 | AM9: 123
A10: Sep 26, 2025 | B10: 68.461914 | C10: =(AE11-AE10)/AE10 -> -0.0023266954 | D10: =(AF11-AF10)/AF10 -> -0.0046983935 | E10: =(AG11-AG10)/AG10 -> 0.011611705 | F10: =(AH11-AH10)/AH10 -> 0.015393821 | G10: 15.92 | H10: =(AI11-AI10)/AI10 -> 0.0087371556 | I10: 914.39001 | J10: =(AI11-AI10)/AI10 -> 0.0087371556 | K10: 27.389112 | L10: =(AJ11-AJ10)/AJ10 -> 0.0064004625 | M10: 119.68153 | N10: =(AK11-AK10)/AK10 -> 0.011726384 | O10: =(AL11-AL10)/AL10 -> -0.026951348 | P10: =(AM11-AM10)/AM10 -> 0.011617443 | Q10: 0.0059 | AC10: 42951 | AE10: 146.13 | AF10: 65.98 | AG10: 64.59 | AH10: 183.84 | AI10: 507.03 | AJ10: 484.34 | AK10: 61.4 | AL10: 57.14 | AM10: 122.23
A11: Sep 29, 2025 | B11: 68.452461 | C11: =(AE12-AE11)/AE11 -> 0.0094656698 | D11: =(AF12-AF11)/AF11 -> 0.0056342318 | E11: =(AG12-AG11)/AG11 -> 0.024793388 | F11: =(AH12-AH11)/AH11 -> -0.021267477 | G11: 15.99 | H11: =(AI12-AI11)/AI11 -> 0.0061392875 | I11: 910.66998 | J11: =(AI12-AI11)/AI11 -> 0.0061392875 | K11: 26.911346 | L11: =(AJ12-AJ11)/AJ11 -> 0.0093139668 | M11: 119.2589 | N11: =(AK12-AK11)/AK11 -> -0.022698004 | O11: =(AL12-AL11)/AL11 -> -0.026258993 | P11: =(AM12-AM11)/AM11 -> 0.0036393045 | Q11: 0.0026 | AC11: 42958 | AE11: 145.79 | AF11: 65.67 | AG11: 65.34 | AH11: 186.67 | AI11: 511.46 | AJ11: 487.44 | AK11: 62.12 | AL11: 55.6 | AM11: 123.65
A12: Sep 30, 2025 | B12: 69.130432 | C12: =(AE13-AE12)/AE12 -> 0.0057756336 | D12: =(AF13-AF12)/AF12 -> 0.0042398546 | E12: =(AG13-AG12)/AG12 -> 0.0052270012 | F12: =(AH13-AH12)/AH12 -> 0.015982485 | G12: 16.65 | H12: =(AI13-AI12)/AI12 -> 0.0065099106 | I12: 915.89001 | J12: =(AI13-AI12)/AI12 -> 0.0065099106 | K12: 27.504433 | L12: =(AJ13-AJ12)/AJ12 -> 0.014695719 | M12: 118.40466 | N12: =(AK13-AK12)/AK12 -> -0.016801186 | O12: =(AL13-AL12)/AL12 -> -0.0024011821 | P12: =(AM13-AM12)/AM12 -> 0.033360193 | Q12: 0.0041 | AC12: 42965 | AE12: 147.17 | AF12: 66.04 | AG12: 66.96 | AH12: 182.7 | AI12: 514.6 | AJ12: 491.98 | AK12: 60.71 | AL12: 54.14 | AM12: 124.1
A13: Oct 1, 2025 | B13: 70.193695 | C13: =(AE14-AE13)/AE13 -> 0.015876233 | D13: =(AF14-AF13)/AF13 -> 0.0069360676 | E13: =(AG14-AG13)/AG13 -> 0.001782796 | F13: =(AH14-AH13)/AH13 -> 0.0095356104 | G13: 16.860001 | H13: =(AI14-AI13)/AI13 -> 0.0033980114 | I13: 937.34003 | J13: =(AI14-AI13)/AI13 -> 0.0033980114 | K13: 27.973963 | L13: =(AJ14-AJ13)/AJ13 -> -0.00042066465 | M13: 118.56968 | N13: =(AK14-AK13)/AK13 -> 0.012899983 | O13: =(AL14-AL13)/AL13 -> 0.03703018 | P13: =(AM14-AM13)/AM13 -> 0.027136619 | Q13: 0.0034 | AC13: 42972 | AE13: 148.02 | AF13: 66.32 | AG13: 67.31 | AH13: 185.62 | AI13: 517.95 | AJ13: 499.21 | AK13: 59.69 | AL13: 54.01 | AM13: 128.24
A14: Oct 2, 2025 | B14: 70.231682 | C14: =(AE15-AE14)/AE14 -> -0.0052537075 | D14: =(AF15-AF14)/AF14 -> -0.010182689 | E14: =(AG15-AG14)/AG14 -> 0.0022245291 | F14: =(AH15-AH14)/AH14 -> 0.00096056353 | G14: 17.450001 | H14: =(AI15-AI14)/AI14 -> -0.0076388755 | I14: 926.5 | J14: =(AI15-AI14)/AI14 -> -0.0076388755 | K14: 28.089283 | L14: =(AJ15-AJ14)/AJ14 -> 0.00072144289 | M14: 118.52443 | N14: =(AK15-AK14)/AK14 -> -0.016209064 | O14: =(AL15-AL14)/AL14 -> 0.05124085 | P14: =(AM15-AM14)/AM14 -> -0.0056938961 | Q14: 0.0006 | AC14: 42979 | AE14: 150.37 | AF14: 66.78 | AG14: 67.43 | AH14: 187.39 | AI14: 519.71 | AJ14: 499 | AK14: 60.46 | AL14: 56.01 | AM14: 131.72
A15: Oct 3, 2025 | B15: 71.494278 | C15: =(AE16-AE15)/AE15 -> -0.0054151625 | D15: =(AF16-AF15)/AF15 -> 0.0083207262 | E15: =(AG16-AG15)/AG15 -> -0.0060668837 | F15: =(AH16-AH15)/AH15 -> 0.032361252 | G15: 18.01 | H15: =(AI16-AI15)/AI15 -> 0.003121728 | I15: 920.28998 | J15: =(AI16-AI15)/AI15 -> 0.003121728 | K15: 29.127188 | L15: =(AJ16-AJ15)/AJ15 -> 0.01027315 | M15: 121.66447 | N15: =(AK16-AK15)/AK15 -> 0.003866846 | O15: =(AL16-AL15)/AL15 -> 0.0020380435 | P15: =(AM16-AM15)/AM15 -> 0.010842178 | Q15: 0.0001 | AC15: 42986 | AE15: 149.58 | AF15: 66.1 | AG15: 67.58 | AH15: 187.57 | AI15: 515.74 | AJ15: 499.36 | AK15: 59.48 | AL15: 58.88 | AM15: 130.97
... A45: Nov 14, 2025 | B45: 89.224876 | C45: =(AE46-AE45)/AE45 -> 0.019132977 | D45: =(AF46-AF45)/AF45 -> 0.0012663571 | E45: =(AG46-AG45)/AG45 -> 0.0032357907 | F45: =(AH46-AH45)/AH45 -> 0.0059395859 | G45: 28.76 | H45: =(AI46-AI45)/AI45 -> 0.01368992 | I45: 1029.27 | J45: =(AI46-AI45)/AI45 -> 0.01368992 | K45: 30.471048 | L45: =(AJ46-AJ45)/AJ45 -> 0.021761544 | M45: 119.68403 | N45: =(AK46-AK45)/AK45 -> 0.0075489139 | O45: =(AL46-AL45)/AL45 -> -0.014227642 | P45: =(AM46-AM45)/AM45 -> -0.0049276022 | Q45: -0.0005 | AC45: 43196 | AE45: 157.32 | AF45: 71.07 | AG45: 71.08 | AH45: 176.78 | AI45: 503.29 | AJ45: 455.85 | AK45: 64.91 | AL45: 49.2 | AM45: 131.91
A46: Total | C46: =AVERAGE(C3:C45)*252 -> 0.49286367 | D46: =AVERAGE(D3:D45)*252 -> 0.36406161 | E46: =AVERAGE(E3:E45)*252 -> 0.43999363 | F46: =AVERAGE(F3:F45)*252 -> -0.34184556 | G46: =AVERAGE(G3:G45)*252 -> 5720.5172 | H46: =AVERAGE(H3:H45)*252 -> 0.016933783 | I46: =AVERAGE(I3:I45)*252 -> 256053.8 | J46: =AVERAGE(J3:J45)*252 -> 0.016933783 | ... Q46: =AVERAGE(Q3:Q45)*252 -> 0.11955349 | AE46: 160.33 | AF46: 71.16 | AG46: 71.31 | AH46: 177.83 | AI46: 510.18 | AJ46: 465.77 | AK46: 65.4 | AL46: 48.5 | AM46: 131.26
A47: StDev | C47: =_xlfn.STDEV.S(C3:C45)*SQRT(252) -> 0.14569785 | D47: =_xlfn.STDEV.S(D3:D45)*SQRT(252) -> 0.17167363 | E47: =_xlfn.STDEV.S(E3:E45)*SQRT(252) -> 0.25674168 | F47: =_xlfn.STDEV.S(F3:G45)*SQRT(252) -> 192.62553 | G47: =_xlfn.STDEV.S(G3:H45)*SQRT(252) -> 192.61478 | H47: =_xlfn.STDEV.S(H3:I45)*SQRT(252) -> 8156.7584 | I47: =_xlfn.STDEV.S(I3:J45)*SQRT(252) -> 8156.7584 | J47: =_xlfn.STDEV.S(J3:K45)*SQRT(252) -> 234.2931 | K47: =_xlfn.STDEV.S(K3:L45)*SQRT(252) -> 234.29602 | L47: =_xlfn.STDEV.S(L3:M45)*SQRT(252) -> 981.87062 | M47: =_xlfn.STDEV.S(M3:N45)*SQRT(252) -> 981.85226 | N47: =_xlfn.STDEV.S(N3:N45)*SQRT(252) -> 0.19359887 | O47: =_xlfn.STDEV.S(O3:O45)*SQRT(252) -> 0.4207418 | P47: =_xlfn.STDEV.S(P3:P45)*SQRT(252) -> 0.19168205 | Q47: =_xlfn.STDEV.S(Q3:Q45)*SQRT(252) -> 0.12543784
A48: Covariance | C48: =_xlfn.COVARIANCE.S(C3:C45,$Q$3:$Q$45)*252 -> 0.001999682 | D48: =_xlfn.COVARIANCE.S(D3:D45,$Q$3:$Q$45)*252 -> -0.0043965732 | E48: =_xlfn.COVARIANCE.S(E3:E45,$Q$3:$Q$45)*252 -> -0.0056679121 | F48: =_xlfn.COVARIANCE.S(F3:F45,$Q$3:$Q$45)*252 -> 0.0030143123 | G48: =_xlfn.COVARIANCE.S(G3:G45,$Q$3:$Q$45)*252 -> -0.065889118 | H48: =_xlfn.COVARIANCE.S(H3:H45,$Q$3:$Q$45)*252 -> 0.01459768 | I48: =_xlfn.COVARIANCE.S(I3:I45,$Q$3:$Q$45)*252 -> -0.44750011 | J48: =_xlfn.COVARIANCE.S(J3:J45,$Q$3:$Q$45)*252 -> 0.01459768 | ... Q48: =_xlfn.COVARIANCE.S(Q3:Q45,$Q$3:$Q$45)*252 -> 0.015734651
A49: Variance | C49: =_xlfn.VAR.S(C3:C45)*252 -> 0.021227864 | D49: =_xlfn.VAR.S(D3:D45)*252 -> 0.029471836 | E49: =_xlfn.VAR.S(E3:E45)*252 -> 0.06591629 | F49: =_xlfn.VAR.S(F3:F45)*252 -> 0.070239447 | G49: =_xlfn.VAR.S(G3:G45)*252 -> 8609.4826 | H49: =_xlfn.VAR.S(H3:H45)*252 -> 0.030836202 | I49: =_xlfn.VAR.S(I3:I45)*252 -> 1465839.9 | J49: =_xlfn.VAR.S(J3:J45)*252 -> 0.030836202 | ... Q49: =_xlfn.VAR.S(Q3:Q45)*252 -> 0.015734651
A50: Beta | C50: =C48/C49 -> 0.094200812 | D50: =D48/D49 -> -0.1491788 | E50: =E48/E49 -> -0.085986516 | F50: =F48/F49 -> 0.042914806 | G50: =G48/G49 -> -7.6530869e-06 | H50: =H48/H49 -> 0.47339423 | I50: =I48/I49 -> -3.052858e-07 | J50: =J48/J49 -> 0.47339423 | ... Q50: =Q48/Q49 -> 1
A51: Jensen Alpha | C51: =C46-($AB46+C50*($Z46-$AB46)) -> 0.49286367 | D51: =D46-($AB46+D50*($Z46-$AB46)) -> 0.36406161 | E51: =E46-($AB46+E50*($Z46-$AB46)) -> 0.43999363 | F51: =F46-($AB46+F50*($Z46-$AB46)) -> -0.34184556 | G51: =G46-($AB46+G50*($Z46-$AB46)) -> 5720.5172 | H51: =H46-($AB46+H50*($Z46-$AB46)) -> 0.016933783 | I51: =I46-($AB46+I50*($Z46-$AB46)) -> 256053.8 | J51: =J46-($AB46+J50*($Z46-$AB46)) -> 0.016933783 | ... P51: =P46-($AB46+P50*($Z46-$AB46)) -> 0.42453953
A52: Treynor I | C52: =(C46-$AB46)/C50 -> 5.2320533 | D52: =(D46-$AB46)/D50 -> -2.440438 | E52: =(E46-$AB46)/E50 -> -5.1170073 | F52: =(F46-$AB46)/F50 -> -7.9656788 | G52: =(G46-$AB46)/G50 -> -7.4747841e+08 | H52: =(H46-$AB46)/H50 -> 0.035770995 | I52: =(I46-$AB46)/I50 -> -8.3873474e+11 | J52: =(J46-$AB46)/J50 -> 0.035770995 | ... P52: =(P46-$AB46)/P50 -> 11.469808
A53: Sharpe | C53: =(C46-$AB46)/C47 -> 3.3827793 | D53: =(D46-$AB46)/D47 -> 2.1206612 | E53: =(E46-$AB46)/E47 -> 1.7137601 | F53: =(F46-$AB46)/F47 -> -0.0017746638 | G53: =(G46-$AB46)/G47 -> 29.699264 | H53: =(H46-$AB46)/H47 -> 2.0760432e-06 | I53: =(I46-$AB46)/I47 -> 31.391613 | J53: =(J46-$AB46)/J47 -> 7.2276062e-05 | ... P53: =(P46-$AB46)/P47 -> 2.2148112
A54: Weights | C54: 0.081875885 | D54: 0.079144389 | E54: 0.081569278 | F54: 0.059741445 | H54: 0.041548726 | J54: 0.060814307 | L54: 0.031815033 | N54: 0.045494251 | O54: 0.051917 | P54: 0.048203728
A55: R_P | C55: =C54*C46 -> 0.04035365 | D55: =D54*D46 -> 0.028813434 | E55: =E54*E46 -> 0.035889963 | F55: =F54*F46 -> -0.020422348 | G55: =G54*G46 -> 0 | H55: =H54*H46 -> 0.00070357711 | I55: =I54*I46 -> 0 | J55: =J54*J46 -> 0.0010298163 | ... AA55: =AA54*AA46 -> 0 | AB55: R_P Total | AD55: =SUM(C55:Z55) -> 0.07872364
A56: Beta | C56: =C50*C54 -> 0.0077127749 | D56: =D50*D54 -> -0.011806665 | E56: =E50*E54 -> -0.007013858 | F56: =F50*F54 -> 0.0025637925 | G56: =G50*G54 -> 0 | H56: =H50*H54 -> 0.019668927 | I56: =I50*I54 -> 0 | J56: =J50*J54 -> 0.028789142 | ... Z56: =Z50*Z54 -> 0 | AB56: Beta Total | AD56: =SUM(C56:Z56) -> 0.050784265
B57: 97.390549 | AC57: 43280
B58: 101.50143 | AC58: 43287
B59: 102.31011 | AC59: 43294
B60: 103.6676 | AC60: 43301
B61: 104.01417 | AC61: 43308
B62: 104.93841 | AC62: 43315
B63: 103.57133 | AC63: 43322
B64: 104.76237 | AC64: 43329
B65: 108.56049 | AC65: 43336
B66: 104.57874 | AC66: 43343
B67: 109.56559 | AC67: 43350
B68: 110.42574 | AC68: 43357
... B211: 260.89999 | AC211: 44358
A212: Total | C212: =AVERAGE(C3:C45)*252 -> 0.49286367 | D212: =AVERAGE(D4:D211)*52 -> 0.60260084 | E212: =AVERAGE(E4:E211)*52 -> -2.0669831 | F212: =AVERAGE(F4:F211)*52 -> 180.60101 | G212: =AVERAGE(G4:G211)*52 -> -7.4745718e+08 | H212: =AVERAGE(H4:H211)*52 -> 8003.4982 | I212: =AVERAGE(I4:I211)*52 -> -8.3873271e+11 | J212: =AVERAGE(J4:J211)*52 -> 230.54167 | K212: =AVERAGE(K4:K211)*52 -> -12635091 | ... AA212: =AVERAGE(AA4:AA211)*52 -> 0 | AB212: =AVERAGE(AB4:AB211) -> #DIV/0!
...

Sheet Correlation 4 years
B1: S&P 500 | C1: NVDA | D1: MSFT | E1: PG | F1: NVO | G1: LMT
A2: S&P 500 | B2: =CORREL([1]RATIOS!Q$3:Q$45,[1]RATIOS!Q$3:Q$45) -> 1 | C2: =CORREL([1]RATIOS!J$3:J$45,[1]RATIOS!Q$3:Q$45) -> 0.66271202 | D2: =CORREL([1]RATIOS!H$3:H$45,[1]RATIOS!Q$3:Q$45) -> 0.66271202 | E2: =CORREL([1]RATIOS!C$3:C$45,[1]RATIOS!Q$3:Q$45) -> 0.1094156 | F2: =CORREL([1]RATIOS!O$3:O$45,[1]RATIOS!Q$3:Q$45) -> 0.12990998 | G2: =CORREL([1]RATIOS!L$3:L$45,[1]RATIOS!Q$3:Q$45) -> 0.13721357
A3: NVDA | B3: =CORREL([1]RATIOS!Q$3:Q$45,[1]RATIOS!J$3:J$45) -> 0.66271202 | C3: 1 | D3: =CORREL([1]RATIOS!H$3:H$45,[1]RATIOS!J$3:J$45) -> 1 | E3: =CORREL([1]RATIOS!C$3:C$45,[1]RATIOS!J$3:J$45) -> 0.255107 | F3: =CORREL([1]RATIOS!O$3:O$45,[1]RATIOS!J$3:J$45) -> 0.17308974 | G3: =CORREL([1]RATIOS!L$3:L$45,[1]RATIOS!J$3:J$45) -> 0.20536707
A4: MSFT | B4: =CORREL([1]RATIOS!Q$3:Q$45,[1]RATIOS!H$3:H$45) -> 0.66271202 | C4: =CORREL([1]RATIOS!J$3:J$45,[1]RATIOS!H$3:H$45) -> 1 | D4: 1 | E4: =CORREL([1]RATIOS!C$3:C$45,[1]RATIOS!H$3:H$45) -> 0.255107 | F4: =CORREL([1]RATIOS!O$3:O$45,[1]RATIOS!H$3:H$45) -> 0.17308974 | G4: =CORREL([1]RATIOS!L$3:L$45,[1]RATIOS!H$3:H$45) -> 0.20536707
A5: PG | B5: =CORREL([1]RATIOS!Q$3:Q$45,[1]RATIOS!C$3:C$45) -> 0.1094156 | C5: =CORREL([1]RATIOS!J$3:J$45,[1]RATIOS!C$3:C$45) -> 0.255107 | D5: =CORREL([1]RATIOS!H$3:H$45,[1]RATIOS!C$3:C$45) -> 0.255107 | E5: 1 | F5: =CORREL([1]RATIOS!O$3:O$45,[1]RATIOS!C$3:C$45) -> 0.16289329 | G5: =CORREL([1]RATIOS!L$3:L$45,[1]RATIOS!C$3:C$45) -> 0.36650544
A6: NVO | B6: =CORREL([1]RATIOS!Q$3:Q$45,[1]RATIOS!O$3:O$45) -> 0.12990998 | C6: 0.40119462 | D6: =CORREL([1]RATIOS!H$3:H$45,[1]RATIOS!O$3:O$45) -> 0.17308974 | E6: =CORREL([1]RATIOS!C$3:C$45,[1]RATIOS!O$3:O$45) -> 0.16289329 | F6: =CORREL([1]RATIOS!O$3:O$45,[1]RATIOS!O$3:O$45) -> 1 | G6: =CORREL([1]RATIOS!L$3:L$45,[1]RATIOS!O$3:O$45) -> 0.056287141
A7: LMT | B7: =CORREL([1]RATIOS!Q$3:Q$45,[1]RATIOS!L$3:L$45) -> 0.13721357 | C7: =CORREL([1]RATIOS!J$3:J$45,[1]RATIOS!L$3:L$45) -> 0.20536707 | D7: =CORREL([1]RATIOS!H$3:H$45,[1]RATIOS!L$3:L$45) -> 0.20536707 | E7: =CORREL([1]RATIOS!C$3:C$45,[1]RATIOS!L$3:L$45) -> 0.36650544 | F7: =CORREL([1]RATIOS!O$3:O$45,[1]RATIOS!L$3:L$45) -> 0.056287141 | G7: =CORREL([1]RATIOS!L$3:L$45,[1]RATIOS!L$3:L$45) -> 1
